Workbook
Name DADOS: #REF!
Name DATA1: #REF!
Name DATA1_1: #REF!
Name DATA10: #REF!
Name DATA10_1: #REF!
Name DATA100: #REF!
Name DATA100_1: #REF!
Name DATA101: #REF!
Name DATA101_1: #REF!
Name DATA102: #REF!
Name DATA102_1: #REF!
Name DATA103: #REF!
Name DATA103_1: #REF!
Name DATA104: #REF!
Name DATA104_1: #REF!
Name DATA105: #REF!
Name DATA105_1: #REF!
Name DATA106: #REF!
Name DATA106_1: #REF!
Name DATA107: #REF!
Name DATA107_1: #REF!
Name DATA108: #REF!
Name DATA108_1: #REF!
Name DATA109: #REF!
Name DATA109_1: #REF!
Name DATA11: #REF!
Name DATA11_1: #REF!
Name DATA110: #REF!
Name DATA110_1: #REF!
Name DATA111: #REF!
Name DATA111_1: #REF!
Name DATA112: #REF!
Name DATA112_1: #REF!
Name DATA113: #REF!
Name DATA113_1: #REF!
Name DATA114: #REF!
Name DATA114_1: #REF!
Name DATA115: #REF!
Name DATA115_1: #REF!
Name DATA116: #REF!
Name DATA116_1: #REF!
Name DATA117: #REF!
Name DATA117_1: #REF!
Name DATA118: #REF!
Name DATA118_1: #REF!
Name DATA119: #REF!
Name DATA119_1: #REF!
Name DATA12: #REF!
Name DATA12_1: #REF!
Name DATA120: #REF!
Name DATA120_1: #REF!
Name DATA121: #REF!
Name DATA121_1: #REF!
Name DATA122: #REF!
Name DATA122_1: #REF!
Name DATA123: #REF!
Name DATA123_1: #REF!
Name DATA124: #REF!
Name DATA124_1: #REF!
Name DATA125: #REF!

Sheet NOTAS
A1: PRIORIDADE LESTE | B1: LEVANTADOR | C1: DATA DESPACHO | D1: ID SISCO | E1: PROTOCOLO | F1: TIPO NOTA | G1: DATA ABERTURA | H1: PRIORIDADE | I1: STATUS SAP | J1: STATUS SISCO | K1: STATUS LIST | L1: FASE | M1: PAT | N1: REGIONAL | O1: MUNICIPIO | P1: DISTANCIA BT | Q1: DISTANCIA MT | R1: DISTANCIA TRAFO | S1: POSTE PREVISTO BT | T1: POSTE PREVISTO MT | U1: NOME | V1: CONTA CONTRATO | W1: INSTALAÇÃO | X1: ENDEREÇO | Y1: LOCALIDADE | Z1: LATITUDE | AA1: LONGITUDE | AB1: INFORMAÇÕES | AC1: TEXTO | AD1: TEXTO_GERAL | CJ1: INFORMAÇÕES EXTRAS
B2: 0 | D2: 660688 | E2: 1106211252 | F2: UNI | G2: 45939 | H2: 0 | I2: CANC | J2: 0 | K2: 0 | L2: MO | M2: PAT1 | N2: CENTRO | O2: PERITORÓ | P2: 35.63 | Q2: 80.77 | R2: 107.66 | S2: 0.89075 | T2: 0.89744444 | U2: ANTONIO MARCOS FERREIRA DA SILVA | V2: 3024429341 | W2: 2001090081 | X2: BR 135 10 / CENTRO | Y2: URBANO | Z2: -4.3844089 | AA2: -44.339222 | AB2: PRÓXIMO A PROFESSORA ROSÂNGELA | CJ2: 09.10.2025 16:58:28 U5511235 20251007008283101 CIENTE DO PRAZO DE 05 DIAS ÚTEIS PARA VISTORIA E EXECUÇÃO DO SERVIÇO. CLIENTE AFIRMA QUE JÁ POSSUI O PADRÃO INSTALADO DENTRO DO LIMITE DA VIA DISJUNTOR: 25A Descrição problema FASE: medidor_monofasico PADRÃO INSTALADO: SIM PONTO DE REFERÊNCIA: PRÓXIMO A PROFESSORA ROSÂNGELA PÚBLICA E CIENTE QUE CASO A INEXISTÊNCIA SEU PEDIDO SERÁ REJEITADO. Rede de BT MAIS APROXIMADA A 100 METROS,CLIENTE JÁ POSSUI PADRÃO MONTADO SOLICITAÇÃO VIA BACKOFFICE (MARANHAO) Nº DO PROTOCOLO DO SITE TELEFONE: (99) 99220-7756
B3: 0 | D3: 662478 | E3: 1108555059 | F3: UNI | G3: 46010 | H3: 0 | I3: REJE | J3: Pré Análise | K3: Notas para expurgos | L3: 0 | M3: PAT1 | N3: LESTE | O3: TIMBIRAS | P3: 9.7 | Q3: 48.54 | R3: 87.61 | S3: 0.2425 | T3: 0.53933333 | U3: WILLYAM DEYVID LIMA CALDAS | V3: 3025006444 | W3: 2001113154 | X3: MARIA CILENE S/N / SANTAREM | Y3: URBANO | Z3: -4.24833 | AA3: -43.933932 | CJ3: 19.12.2025 09:47:12 U5516018 20251203008335532PADRÃO INSTALADO: SIM FASE: MONOFASICO DISJUNTOR: 25 APONTO DE REFERÊNCIA:TELEFONE: (99) 98267-5079CLIENTE AFIRMA QUE JÁ CIENTE QUE CASO A INEXISTÊNCIA SEU PEDIDO SERÁ REJEITADO. CIENTE DO Descrição problema Maior que 100mts POSSUI O PADRÃO INSTALADO DENTRO DO LIMITE DA VIA PÚBLICA E PRAZO DE 05 DIAS ÚTEIS PARA VISTORIA E EXECUÇÃO DO SERVIÇO. SOLICITAÇÃO VIA BACKOFFICE MANº DO PROTOCOLO DO SITE
B4: 0 | D4: 560365 | E4: 1109597721 | F4: UNR | G4: 46043 | H4: 0 | I4: CANC | J4: Liberado para Levantamento | K4: Em levantamento | L4: MO | M4: PAT1 | N4: CENTRO | O4: LIMA CAMPOS | P4: 17.46 | Q4: 10.23 | R4: 70.31 | S4: 0.4365 | T4: 0.11366667 | U4: CELIA PEREIRA DA CRUZ | V4: 3025220667 | W4: 2001121574 | X4: ANTONIO LUCAS CRUZ S/N / CENTRO | Y4: RURAL | Z4: -4.5136508 | AA4: -44.471581 | CJ4: 20260106000198923PADRÃO INSTALADO: SIM FASE: MONOFASICO DISJUNTOR: 21.01.2026 11:49:28 U5514981 25APONTO DE REFERÊNCIA:TELEFONE: (99) 98467-4671CLIENTE AFIRMA QUE JÁ CIENTE QUE CASO A INEXISTÊNCIA SEU PEDIDO SERÁ REJEITADO. CIENTE DO Descrição problema POSSUI O PADRÃO INSTALADO DENTRO DO LIMITE DA VIA PÚBLICA E PRAZO DE 05 DIAS ÚTEIS PARA VISTORIA E EXECUÇÃO DO SERVIÇO. SOLICITAÇÃO VIA BACKOFFICE MANº DO PROTOCOLO DO SITE Sem rede BT para ligar o cliente, rede mas próxima a uns 55 metros, PG do último poste 13036124
B5: 0 | D5: 1894111 | E5: 1109878435 | F5: UNI | G5: 46051 | H5: 0 | I5: CANC | J5: Pré Análise | K5: 0 | L5: MO | M5: PAT1 | N5: CENTRO | O5: PRESIDENTE DUTRA | P5: 44.56 | Q5: 59.95 | R5: 143.21 | S5: 1.114 | T5: 0.66611111 | U5: DANGYLA TASSILA RODRIGUES ALVES CARNIB | V5: 3025294458 | W5: 2001099046 | X5: PRINCIPAL S/N / SAO BENEDITO | Y5: URBANO | Z5: -5.27892 | AA5: -44.479525 | AB5: JDA COMERCIO | CJ5: 29.01.2026 16:34:18 T34411 ATENDIMENTO PRESENCIAL. CEL: 99984626523 CPF REGULAR NA RECEITA: SIM Descrição problema END: RUA PRINCIPAL, S/N, SAO BENEDITO IN: 2001099046 O cliente já é mono mais o cliente que agora rede trifásico mais não tem rede trifásico PADRAO MONO MONTADO NA PAREDE. REF:ESTRADA DA CANAFISTULA SRA DANGYLA TASSILA RODRIGUES ALVES CARNIB SOLICITA REATIVAÇAO NO necessário 90 metros de rede de BT trifásico multiplequisada
B6: 0 | D6: 1894557 | E6: 1109993254 | F6: UNR | G6: 46055 | H6: 0 | I6: CANC | J6: Liberado para Levantamento | K6: Em levantamento | L6: MO | M6: PAT1 | N6: CENTRO | O6: LIMA CAMPOS | P6: 290.93 | Q6: 115.64 | R6: 142.61 | S6: 7.27325 | T6: 1.2848889 | U6: MARIA LUCIA DA CONCEICAO GASPAR | V6: 3025319183 | W6: 2001125364 | X6: SITIO NOVO S/N / CENTRO | Y6: RURAL | Z6: -4.496165 | AA6: -44.571795 | CJ6: ANÁLISE DUP CADASTRO? NÃO 02.02.2026 17:03:53 T12482 ANEXO DOC. DO SOLICITANTE E FORMULÁRIO DE CONEXÃO ASSINADO. CIDADE : LIMA CAMPOS CLIENTE VEIO AO ATENDIMENTO E SOLICITOU CONEXÃO. CIENTE DO PRAZO DE COORD. GEOGRÁFICAS: NÃO APRESENTOU Descrição problema E-MAIL VÁLIDO: NÃO POSSUI ENDEREÇO CORRESPONDÊNCIA: POV SANTO ANTONIO DOS NINAS LIMA CAMPOS ENDEREÇO DA CONEXÃO É O MESMO ENDEREÇO DE CORRESPONDÊNCIA? SIM LOCAL DEMARCADO: NÃO MILHO CONHECIDA COMO DOUTOR PARCELADO: 12 x R$ 36,05 PONTO DE REFERÊNCIA: ENFRENTE A SUA CASA TEM UM PLANTIO DE ARROZ E POSSUI REDE ELÉTRICA PROX. AO IMÓVEL? SIM Rede de BT a 300 metros referência 68056794 SERÁ REJEITADO. TELEFONE: 99981084499 VISTORIA E QUE, EM CASO DE PADRÃO INCOMPLETO/INEXISTENTE, SEU PEDIDO WHATSAPP:99981084499
B7: 0 | D7: 1894891 | E7: 1110247929 | F7: UNI | G7: 46063 | H7: 0 | I7: CANC | J7: Liberado para Levantamento | K7: Em levantamento | L7: MO | M7: PAT1 | N7: CENTRO | O7: VITORINO FREIRE | P7: 26.8 | Q7: 6.47 | R7: 141.87 | S7: 0.67 | T7: 0.071888889 | U7: RENATA BRITO SILVA | V7: 3025388096 | W7: 2001127948 | X7: RUA NAO CADASTRADA S/N / CENTRO | Y7: URBANO | Z7: -4.2786883 | AA7: -45.242538 | AB7: PROX AO MAX BEN GAS. PENULTIMA RUA DO BAIRRO | CJ7: - VITORINO FREIRE MA 10.02.2026 10:16:19 T12653 ANEXO DOC. DO SOLICITANTE, FORMULÁRIO DE CONEXÃO E FORMULÁRIO DE PADRAO ANÁLISE DUP CADASTRO? NÃO AUTORIZAÇÃO BLITZ URBANA? NÃO CLIENTE RENATA BRITO SILVA SOLICITOU CONEXAO NOVA COM COMPADRAO JÁ CLIENTE VEIO AO ATENDIMENTO E SOLICITOU CONEXÃO COM O PADRÃO JÁ COORD. GEOGRÁFICAS: NAO APRESENTOU Cliente fica a 61 metros da rede de baixa tensão, não sendo possível realizar o serviço porque a DEVIDAMENTE MONTADO. CIENTE DO PRAZO DE VISTORIA. Descrição problema E-MAIL VÁLIDO: RENATABRITTO103@GMAIL.COM ENDEREÇO CORRESPONDÊNCIA: AV DOS TUCANOS BAIRRO LUANA LOTE 05 - QD 02 B ENDEREÇO DA CONEXÃO É O MESMO ENDEREÇO DE CORRESPONDÊNCIA? SIM INSTALACAO VIZINHO: 2000906104 LIG. EM PRAÇA PÚBLICA? NAO LOCAL DEMARCADO: SIM MONTADO EM CAMPO MONTADO. NAO
B8: 0 | D8: 1894989 | E8: 1110275419 | F8: UNI | G8: 46064 | H8: 0 | I8: CANC | J8: Pré Análise | K8: 0 | L8: MO | M8: PAT1 | N8: CENTRO | O8: PAULO RAMOS | P8: 75.91 | Q8: 180.62 | R8: 192.78 | S8: 1.89775 | T8: 2.0068889 | U8: JEANNE ARAUJO COSTA | V8: 3025396579 | W8: 2001128522 | X8: I JOAO DA MATA S/N / RES BOA ESPERANCA | Y8: URBANO | Z8: -4.4398283 | AA8: -45.243283 | CJ8: 11.02.2026 09:29:29 U5515375 CIENTE DO PRAZO DE 05 DIAS CLIENTE AFIRMA QUE JÁ POSSUI O PADRÃO INSTALADO DENTRO DO LIMITE DA VIA DISJUNTOR: 25A Descrição problema FASE: Monofásica Não tem rede da equatorial proxima PADRÃO INSTALADO: SIM PONTO DE REFERÊNCIA:NÃO INFORMADO PÚBLICA E CIENTE QUE CASO A INEXISTÊNCIA SEU PEDIDO SERÁ REJEITADO. SOLICITAÇÃO VIA BACKOFFICE MA Nº DO PROTOCOLO DO SITE 20260204000247493 TELEFONE: (98) 98240-3358 ÚTEIS PARA VISTORIA E EXECUÇÃO DO SERVIÇO.
B9: 0 | D9: 1895194 | E9: 1110422398 | F9: UNI | G9: 46069 | H9: 0 | I9: CANC | J9: Pré Análise | K9: 0 | L9: MO | M9: PAT1 | N9: CENTRO | O9: POCAO DE PEDRAS | P9: 133.6 | Q9: 307.41 | R9: 343 | S9: 3.34 | T9: 3.4156667 | U9: PAULO MELO MARTINS | V9: 3025437909 | W9: 2001130190 | X9: MARTINS S/N / NOVA JERUSALEM | Y9: URBANO | Z9: -4.7661183 | AA9: -44.941198 | AB9: FEITO EM 072006 99 9179 5571 PROX A CASA DO SR JOSE | CJ9: 16.02.2026 15:34:43 U5511235 20260212000257469 CIENTE DO PRAZO DE 05 DIAS ÚTEIS PARA VISTORIA E EXECUÇÃO DO SERVIÇO. CLIENTE AFIRMA QUE JÁ POSSUI O PADRÃO INSTALADO DENTRO DO LIMITE DA VIA DISJUNTOR: 25A Descrição problema FASE: medidor_Monofásica Não possui rede BT próxima do local. Sem PG no local PADRÃO INSTALADO: SIM PONTO DE REFERÊNCIA: FEITO EM 072006 99 9179 5571 PROX A CASA DO SR JOSE PÚBLICA E CIENTE QUE CASO A INEXISTÊNCIA SEU PEDIDO SERÁ REJEITADO. SOLICITAÇÃO VIA BACKOFFICE (MARANHAO) Nº DO PROTOCOLO DO SITE TELEFONE: (99) 98527-6572
B10: 0 | D10: 1896486 | E10: 1111146794 | F10: UNR | G10: 46094 | H10: 0 | I10: REJE | J10: Expurgo Concluído | K10: Improdutivo | L10: 0 | M10: PAT3 | N10: LESTE | O10: COLINAS | P10: 1121.26 | Q10: 1235.5 | R10: 1425.26 | S10: 28.0315 | T10: 13.727778 | U10: JOSE OLIVIO DE SA CARDOSO ROSA | V10: 3025639870 | W10: 2001137616 | X10: FAZENDA MANDIOCAL S/N / PORTO ALEGRE | Y10: RURAL | Z10: -5.9224861 | AA10: -44.417462 | AB10: FINAL DO PV CENTRO DO FELIANO, PROX AO CARISVALDO, TRATA-SE DA FAZENDA MANDIOCAL DO ZE OLIVIO, A 4KM | CJ10: 98 8115-5438 ASSINOU FORMULÁRIO DE FINANC. DE PADRÃO? SIM *CLIENTE VEIO AO 13.03.2026 15:22:10 T12500 ANÁLISE DUP CADASTRO? NÃO ATENDIMENTO E SOLICITOU CONEXÃO COM FINANCIAMENTO DE PADRÃO. CIENTE DO AUTORIZAÇÃO BLITZ URBANA? NÃO CC / MD VIZINHO 8686289 /11521903599 COORD. GEOGRÁFICAS: 5.910067600000- 44.417774400000- ; Descrição problema E-MAIL VÁLIDO: VICTORPCROSA@GMAILCOM ENDEREÇO CORRESPONDÊNCIA: FAZENDA MANDIOCAL, PORTO ALEGRE, COLINAS-MA ENDEREÇO DA CONEXÃO É O MESMO ENDEREÇO De CORRESPONDÊNCIA? SIM FELICIANO, PROX AO HAIRAM, PROX AO RENATO FORMULÁRIO DE FINACIAMENTO DE PADRÃO ASSINADOS. LIG. EM PRAÇA PÚBLICA? NÃO LIGAÇÃO NOVA COM FINANCIAMENTO DE PADRAO LOCAL DEMARCADO:NÃO NÃO POSSUI REDE PROX. AO IMÓVEL? NÃO OBS: ENTRAR EM CONTATO COM CLIENTE, DEVIDO AO ACESSO VICTOR ROSA FONE: PADRÃO FINANCIADO: PFC7
B11: 0 | D11: 1907572 | E11: 1111250867 | F11: UNI | G11: 46098 | H11: GIRO NO PRAZO | I11: CANC | J11: Pré Análise | K11: Em levantamento | L11: MO | M11: PAT1 | N11: CENTRO | O11: TRIZIDELA DO VALE | P11: 30.18 | Q11: 19.89 | R11: 107.09 | S11: 0.7545 | T11: 0.221 | U11: MARIA VILANIR DOS SANTOS PIMENTEL | V11: 3025668609 | W11: 2001138628 | X11: STO ANTONIO 12 / STO ANTONIO | Y11: URBANO | Z11: -4.5615467 | AA11: -44.61974 | CJ11: 17.03.2026 17:11:02 T12482 ANEXO DOC. DO SOLICITANTE, FORMULÁRIO DE CONEXÃO E FORMULÁRIO DE PADRAO ANÁLISE DUP CADASTRO? NÃO AUTORIZAÇÃO BLITZ URBANA? NÃO CLIENTE SOLICITOU CONEXAO NOVA COM COMPADRAO JÁ MONTADO EM CAMPO CLIENTE VEIO AO ATENDIMENTO E SOLICITOU CONEXÃO COM O PADRÃO JÁ COORD. GEOGRÁFICAS: XXXXXXXXXX DEVIDAMENTE MONTADO. CIENTE DO PRAZO DE VISTORIA. Descrição problema E-MAIL VÁLIDO: NÃO APRESENTOU ENDEREÇO CORRESPONDÊNCIA: ENDEREÇO DA CONEXÃO É O MESMO ENDEREÇO DE CORRESPONDÊNCIA? SIM Falta construir rede de BT pra atender o cliente a mais do limite permitido pela equatorial INSTALACAO VIZINHO: XXXXXXXXXX LIG. EM PRAÇA PÚBLICA? LOCAL DEMARCADO: SIM MONTADO. NAO PONTO DE REFERÊNCIA: ENFRENTE A CASA DO SIM CONSTRURORA . RUA SEM SAIDA POSSUI REDE PROX. AO IMÓVEL? SIM
B12: 0 | D12: 1907612 | E12: 1111279625 | F12: UNI | G12: 46099 | H12: 0 | I12: REJE | J12: Pré Análise | K12: 0 | L12: 0 | M12: PAT2 | N12: CENTRO | O12: VARGEM GRANDE | P12: 413.66 | Q12: 156.5 | R12: 226.52 | S12: 10.3415 | T12: 1.7388889 | U12: JECIARA SANTOS DE ANDRADE | V12: 3025679660 | W12: 2001139018 | X12: PROJETADA 1 S/N / TRIZIDELA | Y12: URBANO | Z12: -3.5612347 | AA12: -43.919498 | AB12: LT 06 QD 12 PROJETADA 23 | CJ12: "CLIENTE JECIARA SANTOS DE ANDRADE SOLICITOU CONEXAO NOVA COM 06 QUADRA 12 ZONA URBANA DE VARGEM GRANDE MA 18.03.2026 15:56:28 T35429 ANEXO DOC. DO SOLICITANTE, FORMULÁRIO DE CONEXÃO E FORMULÁRIO DE ANÁLISE DUP CADASTRO? NÃO ASSINOU FORMULÁRIO DE FINANC. DE PADRÃO? SIM AUTORIZAÇÃO BLITZ URBANA? NÃO CLIENTE VEIO AO ATENDIMENTO E SOLICITOU CONEXÃO COM FINANCIAMENTO DE COORD. GEOGRÁFICAS: NAO INFORMADO Descrição problema E-MAIL VÁLIDO: NÃO APRESENTOU ENDEREÇO CORRESPONDÊNCIA:LOTEAMENTO NOVA ALIANCA RUA PROJETDA III LOTE ENDEREÇO DA CONEXÃO É O MESMO ENDEREÇO DE CORRESPONDÊNCIA? NAO FINACIAMENTO DE PADRÃO ASSINADOS." FINANCIAMENTO DE PADRAO FPC7 INSTALACAO VIZINHO: NAO INFORMADO LIG. EM PRAÇA PÚBLICA?NAO LOCAL DEMARCADO: SIM NAO PADRÃO FINANCIADO: SIM
B13: 0 | D13: 1912223 | E13: 1111929860 | F13: UNI | G13: 46121 | H13: 0 | I13: CANC | J13: Liberado para Levantamento | K13: Em levantamento | L13: TR | M13: PAT1 | N13: CENTRO | O13: ESPERANTINÓPOLIS | P13: 23.95 | Q13: 19 | R13: 52.9 | S13: 0.59875 | T13: 0.21111111 | U13: MUNICIPIO DE ESPERANTINOPOLIS | V13: 3025856561 | W13: 2001145198 | X13: GENESIO CARVALHO S/N / CENTRO | Y13: URBANO | Z13: -4.88372 | AA13: -44.880895 | AB13: MEDIDOR REFERÊNCIA – 3703-019415-3 | CJ13: (99) 98849-9579 Oi (99) 99141-0688 Claro -------------- Mensagem original -------------- 09.04.2026 21:36:53 U5510610 30 AVISO: Este e-mail foi originado de fora do Grupo Equatorial Energia. Assunto: De: Kleber Carneiro [klebercarneiro10@gmail.com] Descrição problema Enviado: 09/04/2026 13:56 Grato, Kléber Carneiro Não clique em links ou abra anexos, a menos que reconheça o remetente e Para: laise.rabelo@equatorialenergia.com.br; artemilton.torres@equatorialenergia.com.br; grandesclientes.maranhao@equatorialenergia.com.br saiba que o conteúdo é seguro.
B14: 0 | D14: 1974648 | E14: 1112194457 | F14: UNI | G14: 46132 | H14: 0 | I14: REJE | J14: Pré Análise | K14: Em levantamento | L14: 0 | M14: PAT1 | N14: NORTE | O14: SANTA RITA | P14: 88.58 | Q14: 86.62 | R14: 73.82 | S14: 2.2145 | T14: 0.96244444 | U14: ELENILTON BARDOSA | V14: 3025931687 | W14: 2001147773 | X14: PRINCIPAL S/N / POVOADO CASCAVEL | Y14: URBANO | Z14: -3.1887667 | AA14: -44.25205 | CJ14: ,20)* 20.04.2026 11:44:58 T40239 ANEXO DOC. DO SOLICITANTE E FORMULÁRIO DE CONEXÃO ASSINADO. ANÁLISE DUP CADASTRO? SIM / NÃO ATO DA REALIZAÇÃO SERVIÇO. VALOR DE R$ 57,20 (PARC DE 1 VEZES DE R$57 CHECKLIST PADRÃO MONTADO ASSINADO PELO CLIENTE? SIM / CLIENTE VEIO AO ATENDIMENTO E SOLICITOU CONEXÃO. CIENTE DO PRAZO DE COORD. GEOGRÁFICAS: NAO MAPEADO Descrição problema E-MAIL VÁLIDO: ELENILTON BARDOSA ENDEREÇO CORRESPONDÊNCIA: RU APRINCIPAL, POVOADO CASCAVEL CIDADE SANTA ENDEREÇO DA CONEXÃO É O MESMO ENDEREÇO DE CORRESPONDÊNCIA? SIM FINANCIAMENTO PARCIAL DE PADRÃO DO DISJUNTOR, CASO ESTEJA PENDENTE NO PADRÃO INSTALADO EXTERNAMENTE? SIM / NÃO PONTO DE REFERÊNCIA: PROXIMO AO SITIO SAO JOSE POSSUI REDE ELÉTRICA PROX. AO IMÓVEL? SIM / RITA-MA SERÁ REJEITADO. Sem rede falta de padrão cliente ainda não se pradronizou
B15: 0 | D15: 1978181 | E15: 1112533746 | F15: UNR | G15: 46146 | H15: 0 | I15: REJE | J15: Pré Análise | K15: 0 | L15: 0 | M15: PAT2 | N15: CENTRO | O15: GONÇALVES DIAS | P15: 826.64 | Q15: 123.61 | R15: 1238.78 | S15: 20.666 | T15: 1.3734444 | U15: ANGRA CRISTINA DAMACENA FIGUEIREDO | V15: 3026069016 | W15: 2001152035 | X15: PRINCIPAL S/N / CENTRO | Y15: RURAL | Z15: -5.0797569 | AA15: -44.149557 | AB15: NO COMECO DO POVOADO, LUZIA | CJ15: 04.05.2026 11:38:37 T16550 A INSTALAÇÃO POSSUI OU CONTARÁ COM CARREGADORES PARA VEÍCULOS ELÉTRICOS? AMPERAGEM DO DISJUNTOR: 25A ANEXO DOC. DO SOLICITANTE E FORMULÁRIO DE CONEXÃO ASSINADO. ANÁLISE DUP CADASTRO? SIM CASO SIM, INFORMAR DADOS DO CARREGADOR : (Potência e modelo da estação CHECKLIST PADRÃO MONTADO ASSINADO PELO CLIENTE? SIM CLIENTE VEIO AO ATENDIMENTO E SOLICITOU CONEXÃO. CIENTE DO PRAZO DE COORD. GEOGRÁFICAS: 5.073342700000, 44.158955400000 SEM REDE PROXIMA Cliente sem rede de Mt a rede de MT passar em frente a casa do cliente fica só 5 metros da casa Descrição problema E-MAIL VÁLIDO: XXXXXXXXXXXXXXXXXXXXXXXXXXXXXXXXXXXXX ENDEREÇO CORRESPONDÊNCIA: PV LARGES ZONA RURAL ENDEREÇO DA CONEXÃO É O MESMO ENDEREÇO DE CORRESPONDÊNCIA? SIM Expansão rural, não possui rede de bt para atender o cliente,cliente ja possui o padrão montado. FICA UNS 1000M DE DISTANCIA DA REDE INSTALAÇÃO DO VIZINHO: 37977969 Necessidade de obra, no endereço da ligação não possui rede de BT, passa a rede de MT monofasico a PADRÃO INSTALADO EXTERNAMENTE? SIM PONTO DE REFERÊNCIA: LUIZA MARIA, NO COMECO DO POVOADO,
B16: 0 | D16: 1978188 | E16: 1112535950 | F16: UNR | G16: 46146 | H16: 0 | I16: REJE | J16: Pré Análise | K16: 0 | L16: 0 | M16: PAT3 | N16: LESTE | O16: SUCUPIRA DO RIACHÃO | P16: 3494.76 | Q16: 2688.79 | R16: 2636.68 | S16: 87.369 | T16: 29.875444 | U16: RITA MARIA DOS SANTOS SOUSA | V16: 3026068656 | W16: 2001152144 | X16: MATA S/N / RURAL | Y16: RURAL | Z16: -6.4013033 | AA16: -43.548266 | CJ16: TELEFONE: (99) 98487-4227 04.05.2026 14:06:41 U5512834 20260428000398591 8 km do poste 1004231 CLASSE DE CONSUMO: RESIDENCIAL Descrição problema Endereço não localizado NOME DO CLIENTE: RITA MARIA DOS SANTOS SOUSA SOLICITA FINANCIAMENTO DE PADRÃO PARCELADO EM: 024 PONTO DE REFERÊNCIA: NÃO TEM APELIDO: NÃO INFORMADO SOLICITAÇÃO VIA BACKOFFICE (MA) Nº DO PROTOCOLO DO SITE TIPO DE FASE: MONOFÁSICO:
B17: 0 | D17: 1980140 | E17: 1112567806 | F17: UNR | G17: 46147 | H17: 0 | I17: REJE | J17: Pré Análise | K17: 0 | L17: 0 | M17: PAT2 | N17: SUL | O17: GRAJAÚ | P17: 338.06 | Q17: 264.43 | R17: 266.07 | S17: 8.4515 | T17: 2.9381111 | U17: ISAEL DO ESPIRITO SANTO DOS SANTOS | V17: 3026078465 | W17: 2001152422 | X17: CHACARA SANTA LUZIA S/N / ZONA RURAL | Y17: RURAL | Z17: -5.7393717 | AA17: -46.267075 | AB17: PROXIMO A INSTALAÇÃO 41908939 , DEPOIS DA BELA ESTRELA. | CJ17: 05.05.2026 10:00:56 T53617 ? NAO A INSTALAÇÃO POSSUI OU CONTARÁ COM CARREGADORES PARA VEÍCULOS ELÉTRICOS AMPERAGEM DO DISJUNTOR : 25A ANEXO DOC. DO SOLICITANTE, FORMULÁRIO DE CONEXÃO E FORMULÁRIO DE ANÁLISE DUP CADASTRO? NÃO ASSINOU FORMULÁRIO DE FINANC. DE PADRÃO? SIM CARREGADOR : XXXXXXXXXXXXXX CHECKLIST PADRÃO MONTADO ASSINADO PELO CLIENTE? NÃO CIENTE DO PRAZO DE VISTORIA. CLIENTE: ISAEL DO ESPIRITO SANTO DOS SANTOS COORD. GEOGRÁFICAS: NAO LOCALIZADAS Cliente fica a 150 metros dessa instalação 41908939 Descrição problema E-MAIL VÁLIDO: ISAEL2533@GMAIL.COM ENDEREÇO CORRESPONDÊNCIA: CHACARA SANTA LUZIA, S/N, ZONA RURAL. ENDEREÇO DA CONEXÃO É O MESMO ENDEREÇO DE CORRESPONDÊNCIA? SIM ESTRELA. FINACIADO EM 24X DE 18,03 FINACIAMENTO DE PADRÃO ASSINADOS.
B18: 0 | D18: 1980788 | E18: 1112633274 | F18: UNI | G18: 46149 | H18: GIRO NO PRAZO | I18: CANC | J18: Pré Análise | K18: 0 | L18: MO | M18: PAT1 | N18: CENTRO | O18: PRESIDENTE DUTRA | P18: 20.07 | Q18: 21.53 | R18: 65.09 | S18: 0.50175 | T18: 0.23922222 | U18: LUIS ANTONIO LINDOLFO DA SILVA | V18: 3026103494 | W18: 2001153294 | X18: PRINCIPAL S/N / PARQUE DOS IPES | Y18: URBANO | Z18: -5.2934356 | AA18: -44.478846 | AB18: MEDIDOR VIZINHO 37030079427 | CJ18: 07.05.2026 10:20:12 T34411 ANEXO DOC. DO SOLICITANTE E FORMULÁRIO DE CONEXÃO ASSINADO CHECKLIST PADRÃO MONTADO ASSINADO PELO CLIENTE? SIM CLIENTE VEIO AO ATENDIMENTO E SOLICITOU CONEXÃO. CIENTE DO PRAZO DE COORD. GEOGRÁFICAS: 5.292562620000- 44.478204560000- Descrição problema ENDEREÇO CORRESPONDÊNCIA: RD BR 226, PARQUE DOS IPES, S/N, CENTRO NOVA. Necessário construção de rede BT e MT para atender o cliente, rede MT mais próxima fica a 600m PADRÃO INSTALADO EXTERNAMENTE? SIM PONTO DE REFERÊNCIA: MEDIDOR VIZINHO 37030079427 POSSUI REDE ELÉTRICA PROX. AO IMÓVEL? SIM SERÁ REJEITADO. Sr. LUIS ANTONIO LINDOLFO DA SILVA VEIO AO ATENDIMENTO SOLICITAR LIGAÇÃO TELEFONE: 99991276318 VISTORIA E QUE, EM CASO DE PADRÃO INCOMPLETO/INEXISTENTE, SEU PEDIDO WHATSAPP: 99991276318
B19: 0 | D19: 1983481 | E19: 1112769193 | F19: UNR | G19: 46154 | H19: 0 | I19: REJE | J19: Pré Análise | K19: 0 | L19: 0 | M19: PAT3 | N19: LESTE | O19: SUCUPIRA DO RIACHÃO | P19: 1887.87 | Q19: 1912.57 | R19: 1889.72 | S19: 47.19675 | T19: 21.250778 | U19: JOSE FRANCISCO SILVA DOS SANTOS | V19: 3026146738 | W19: 2001154830 | X19: MATA S/N / RURAL | Y19: RURAL | Z19: -6.3681814 | AA19: -43.573366 | CJ19: 12.05.2026 16:32:06 U5514207 20260507000416598 CIENTE QUE CASO A INEXISTÊNCIA SEU PEDIDO SERÁ REJEITADO. CIENTE DO CLIENTE AFIRMA QUE JÁ POSSUI O PADRÃO INSTALADO DENTRO DO LIMITE DA VIA Descrição problema FASE: MONOFASICO DISJUNTOR: SIM PADRÃOINSTALADO: NÃO FINANCIAMENTO 24X PONTO DE REFERÊNCIA: PROX POCO ARTESIANO DA MATA PRAZO DE 05 DIAS PÚBLICA E SOLICITAÇÃO VIA BACKOFFICE (EQUATORIAL MARANHÂO) Nº DO PROTOCOLO DO SITE Sem rede e cliente aceita financiamento 1004231 PG fica a 9km TELEFONE: (99) 98425-1166 ÚTEIS PARA VISTORIA E EXECUÇÃO DO SERVIÇO.
B20: 0 | D20: 1987035 | E20: 1112956037 | F20: UNI | G20: 46162 | H20: 0 | I20: REJE | J20: Pré Análise | K20: 0 | L20: 0 | M20: PAT1 | N20: NOROESTE | O20: CENTRO DO GUILHERME | P20: 18.86 | Q20: 134.4 | R20: 154.1 | S20: 0.4715 | T20: 1.4933333 | U20: KELTON DOUGLAS DUTRA | V20: 3026214148 | W20: 2001157176 | X20: VILA DO VAL S/N / VILA DO VAL | Y20: URBANO | Z20: -2.45833 | AA20: -46.04876 | CJ20: 20.05.2026 09:22:18 U5512834 CIENTE DO PRAZO DE 05 DIAS ÚTEIS PARA VISTORIA E EXECUÇÃO DO SERVIÇO. CLIENTE AFIRMA QUE JÁ POSSUI O PADRÃO INSTALADO DENTRO DO LIMITE DA VIA Cliente nao montou seu pradao e nao tem rede pra ligar o cliente Cliente sem pontalete sem disjuntor sem aterramento sem eletroduto sem estalacao Cliente orientado Descrição problema ENDEREÇO: RUA 03, lotes 16 e 17 do lado esquerdo - vila do val. centro Nº DO PROTOCOLO DO SITE 20260519000439489 PADRÃO INSTALADO: SIM FASE: MONOFÁSICO DISJUNTOR: 25A PONTO DE REFERÊNCIA: lotes 16 e 17 do lado esquerdo PÚBLICA E CIENTE QUE CASO A INEXISTÊNCIA SEU PEDIDO SERÁ REJEITADO. SOLICITAÇÃO VIA BACKOFFICE MA TELEFONE: (98) 98204-6902 a se padronizar do guilherme CEP 65288000
B21: 0 | D21: 1987700 | E21: 1113020981 | F21: UNR | G21: 46164 | H21: 0 | I21: REJE | J21: Pré Análise | K21: 0 | L21: 0 | M21: PAT3 | N21: NORTE | O21: MORROS | P21: 3440.23 | Q21: 3462.87 | R21: 3457.18 | S21: 86.00575 | T21: 38.476333 | U21: EDILSON MARQUES DOS SANTOS | V21: 3026237326 | W21: 2001157933 | X21: PV BARRO BRANCO S/N / PV BARRO BRANCO | Y21: RURAL | Z21: -2.98846 | AA21: -43.757403 | CJ21: Cliente a 3km a frente ,sem acesso ao local. 22.05.2026 08:47:31 U5513369 CLASSE DE CONSUMO: RESIDENCIAL Descrição problema NOME DO CLIENTE: EDILSON MARQUES DOS SANTOS Nº DO PROTOCOLO DO SITE 20260521000444621 PARCELADO EM: 24 VEZES NO VALOR DE R$18,03. PONTO DE REFERÊNCIA: NÃO INFORMADO SOLICITAÇÃO DE LIGAÇÃO COM FINANCIAMENTO DE PADRÃO VIA SITE (MA) Sem rede TELEFONE: (98) 9929-1559 TIPO DE FASE: monofásico
B22: 0 | D22: 1986240 | E22: 1113027419 | F22: UNI | G22: 46164 | H22: 0 | I22: CANC | J22: Pré Análise | K22: 0 | L22: MO | M22: PAT1 | N22: CENTRO | O22: VARGEM GRANDE | P22: 46.58 | Q22: 38.79 | R22: 60.42 | S22: 1.1645 | T22: 0.431 | U22: ITAYANARA MARTINS DIAS | V22: 3026245230 | W22: 2001158235 | X22: PROJETADA S/N / SAO FRANCISCO | Y22: URBANO | Z22: -3.544805 | AA22: -43.927422 | AB22: INSTALAÇÃO : 45073173 VILA DA DODO | CJ22: COORD. GEOGRÁFICAS: LAT 3.545078000000- ; LONG 43.927388790000- 22.05.2026 15:55:32 T41311 ? NÃO A INSTALAÇÃO POSSUI OU CONTARÁ COM CARREGADORES PARA VEÍCULOS ELÉTRICOS AMPERAGEM DO DISJUNTOR : 25 A ANEXO DOC. DO SOLICITANTE E FORMULÁRIO DE CONEXÃO ASSINADO. ANÁLISE DUP CADASTRO?NÃO CHECKLIST PADRÃO MONTADO ASSINADO PELO CLIENTE? SIM DO PRAZO DE VISTORIA E QUE, EM CASO DE PADRÃO INCOMPLETO/INEXISTENTE, Descrição problema E-MAIL VÁLIDO: XXXXXXXXXXXXXXXXXXXXXXXXXXXXXXXXXXXXX ENDEREÇO CORRESPONDÊNCIA: RUA PROJETADA I S/N SAO FRANCISCO VARGEM ENDEREÇO DA CONEXÃO É O MESMO ENDEREÇO DE CORRESPONDÊNCIA? SIM GRANDE MA INSTALAÇÃO : 45073173 ITAYANARA MARTINS DIAS VEIO AO ATENDIMENTO E SOLICITOU CONEXÃO. CIENTE PADRÃO INSTALADO EXTERNAMENTE? SIM PONTO DE REFERÊNCIA: VILA DA DODO POSSUI REDE ELÉTRICA PROX. AO IMÓVEL? SIM SEU PEDIDO SERÁ REJEITADO.
B23: 0 | D23: 1988781 | E23: 1113028488 | F23: UNI | G23: 46164 | H23: GIRO NO PRAZO | I23: CANC | J23: Pré Análise | K23: 0 | L23: MO | M23: PAT1 | N23: CENTRO | O23: VARGEM GRANDE | P23: 40.07 | Q23: 33.33 | R23: 61.06 | S23: 1.00175 | T23: 0.37033333 | U23: ITAYANARA MARTINS DIAS | V23: 3026245531 | W23: 2001158300 | X23: PROJETADA S/N / SAO FRANCISCO | Y23: URBANO | Z23: -3.5447667 | AA23: -43.927436 | AB23: INSTALAÇÃO : 45073173 VILA DA DODO | CJ23: COORD. GEOGRÁFICAS: LAT 3.545078000000- ; LONG 43.927388790000- 22.05.2026 16:57:41 T41311 ? NÃO A INSTALAÇÃO POSSUI OU CONTARÁ COM CARREGADORES PARA VEÍCULOS ELÉTRICOS AMPERAGEM DO DISJUNTOR : 25 A ANEXO DOC. DO SOLICITANTE E FORMULÁRIO DE CONEXÃO ASSINADO. ANÁLISE DUP CADASTRO?NÃO CHECKLIST PADRÃO MONTADO ASSINADO PELO CLIENTE? SIM DO PRAZO DE VISTORIA E QUE, EM CASO DE PADRÃO INCOMPLETO/INEXISTENTE, Descrição problema E-MAIL VÁLIDO: XXXXXXXXXXXXXXXXXXXXXXXXXXXXXXXXXXXXX ENDEREÇO CORRESPONDÊNCIA: RUA PROJETADA I S/N SAO FRANCISCO VARGEM ENDEREÇO DA CONEXÃO É O MESMO ENDEREÇO DE CORRESPONDÊNCIA? SIM GRANDE MA INSTALAÇÃO : 45073173 ITAYANARA MARTINS DIAS VEIO AO ATENDIMENTO E SOLICITOU CONEXÃO. CIENTE PADRÃO INSTALADO EXTERNAMENTE? SIM PONTO DE REFERÊNCIA: VILA DA DODO POSSUI REDE ELÉTRICA PROX. AO IMÓVEL? SIM SEU PEDIDO SERÁ REJEITADO.
B24: 0 | D24: 1987729 | E24: 1113050143 | F24: UNI | G24: 46165 | H24: 0 | I24: REJE | J24: Pré Análise | K24: 0 | L24: 0 | M24: PAT1 | N24: NOROESTE | O24: MIRINZAL | P24: 253.21 | Q24: 67.62 | R24: 349.48 | S24: 6.33025 | T24: 0.75133333 | U24: ANTONIO JOSE ARAUJO CRUZ | V24: 3026248034 | W24: 2001158360 | X24: MACHIXE S/N / MAXIXE | Y24: URBANO | Z24: -2.184715 | AA24: -44.917492 | CJ24: 23.05.2026 08:25:52 U5515486 CLASSE DE CONSUMO: RESIDENCIAL Descrição problema FINANCIAMENTO NOME DO CLIENTE: ANTONIO JOSE ARAUJO CRUZ SOLICITA FINANCIAMENTO DE Nº DO PROTOCOLO DO SITE 20260520000443882 PADRÃO PARCELADO EM: 024 VEZES PONTO DE REFERÊNCIA: XXXXXXXX SOLICITAÇÃO VIA BACKOFFICE MARANHÃO TELEFONE: (98) 98545-7279 TIPO DE FASE: MONOFÁSICO sem rede cliente aceita financiamento
B25: 0 | D25: 651006 | E25: 1089090493 | F25: UNI | G25: 45411 | H25: 0 | I25: ATIV | J25: Pré Análise | K25: 0 | L25: BT | M25: PAT3 | N25: NOROESTE | O25: BOA VISTA DO GURUPI | P25: 0 | Q25: 0 | R25: 0 | S25: 0 | T25: 0 | U25: RAIMUNDO NONATO FERREIRA LOPES | V25: 3020627122 | W25: 2000931988 | X25: RUA NAO CADASTRADA S/N / RURAL | Y25: RURAL | Z25: 0 | AA25: 0 | AB25: A DIREITA SO SR. SERROTE | CJ25: Descrição problema PADRÃO INSTALADO: SIM FASE: monofasico DISJUNTOR: 50A A distância da MT para casa do cliente é de 1.200 mts TELEFONE:98985421755 SOLICITAÇÃO VIA BACKOFFICE MA Nº DO PROTOCOLO DO SITE 20240429006275096 PÚBLICA E CIENTE QUE CASO A INEXISTÊNCIA SEU PEDIDO SERÁ REJEITADO. PONTO DE REFERÊNCIA: A DIREITA SO SR. SERROTE 29.04.2024 14:45:51 U5513960 CIENTE DO PRAZO DE 05 DIAS ÚTEIS PARA VISTORIA E EXECUÇÃO DO SERVIÇO. ENDEREÇO:POVOADO VILA JAPARIQUARA CLIENTE AFIRMA QUE JÁ POSSUI O PADRÃO INSTALADO DENTRO DO LIMITE DA VIA
B26: 0 | D26: 1988835 | E26: 1113120631 | F26: UNR | G26: 46169 | H26: 0 | I26: REJE | J26: Pré Análise | K26: Em levantamento | L26: 0 | M26: PAT1 | N26: NOROESTE | O26: MIRINZAL | P26: 75.44 | Q26: 83.33 | R26: 85.6 | S26: 1.886 | T26: 0.92588889 | U26: JOINA BASTOS TRINDADE | V26: 3026274582 | W26: 2001159471 | X26: RUA NAO CADASTRADA S/N / RURAL | Y26: RURAL | Z26: -2.1282917 | AA26: -44.782217 | CJ26: 20260526000453726 27.05.2026 09:17:30 U5513370 APELIDO: NÃO INFORMADO CLASSE DE CONSUMO: RESIDENCIAL Descrição problema NOME DO CLIENTE: JOINA BASTOS TRINDADE FINANCIAMENTO DE PADRÃO PARCELADO EM: 024 PONTO DE REFERÊNCIA: NÃO INFORMADO SEM rede MT e bt no local SOLICITAÇÃO VIA BACKOFFICE (MA) Nº DO PROTOCOLO DO SITE TELEFONE: (98) 98501-5374 TIPO DE FASE: MONOFÁSICO: medidor_monofasico cliente aceita financiamento
B27: FABIO ALTINO DE SOUZA JUNIOR | C27: 46265 | D27: 2305462 | E27: 1113154784 | F27: UNI | G27: 46170 | H27: 0 | I27: REJE | J27: Liberado para Levantamento | K27: Em levantamento | L27: 0 | M27: PAT2 | N27: SUL | O27: JOAO LISBOA | P27: 593.52 | Q27: 36.1 | R27: 71.13 | S27: 14.838 | T27: 0.40111111 | U27: MARIA DE JESUS SANTOS DE ARAUJO | V27: 3026292564 | W27: 2001160151 | X27: MURAJUBA S/N / LOTEAMENTO MURAJUBA | Y27: URBANO | Z27: -5.3341089 | AA27: -47.405755 | AB27: PRÓXIMO A FAZENDA CHAPARRAL | CJ27: 28.05.2026 14:25:50 T27855 ?NAO A INSTALAÇÃO POSSUI OU CONTARÁ COM CARREGADORES PARA VEÍCULOS ELÉTRICOS AMPERAGEM DO DISJUNTOR : ANEXO DOC. DO SOLICITANTE, FORMULÁRIO DE CONEXÃO E FORMULÁRIO DE ANÁLISE DUP CADASTRO? SIM / ASSINOU FORMULÁRIO DE FINANC. DE PADRÃO? SIM / CHECKLIST PADRÃO MONTADO ASSINADO PELO CLIENTE? SIM / CLIENTE Sra. MARIA DE JESUS SANTOS DE ARAUJO VEIO AO ATENDIMENTO E COORD. GEOGRÁFICAS: NAO LOCALIZADA ; Descrição problema E-MAIL VÁLIDO: NAO INFORMADO ENDEREÇO CORRESPONDÊNCIA: XXXXXXXXXXXXXXXXXXXXXXXXXXXXXXXXXXXXX ENDEREÇO DA CONEXÃO É O MESMO ENDEREÇO DE CORRESPONDÊNCIA? SIM / FINACIAMENTO DE PADRÃO ASSINADOS. IMOVEL LOCALIZADO NA AREA URBANA LIGAÇÃO NOVA – COM FINANCIAMENTO DE PADRÃO PADRAO FINANCIADO: ( X ) SIM FPC7 PADRÃO INSTALADO EXTERNAMENTE? SIM / PONTO DE REFERÊNCIA: Próximo a fazenda chaparral
B28: 0 | D28: 2305485 | E28: 1113194562 | F28: UNR | G28: 46171 | H28: GIRO NO PRAZO | I28: CANC | J28: Pré Análise | K28: 0 | L28: MO | M28: PAT2 | N28: CENTRO | O28: NINA RODRIGUES | P28: 948.15 | Q28: 28.78 | R28: 111.64 | S28: 23.70375 | T28: 0.31977778 | U28: RAIMUNDA DO LAGO CASTRO | V28: 3026308533 | W28: 2001160805 | X28: RUA NAO CADASTRADA S/N / RURAL | Y28: RURAL | Z28: -3.4491242 | AA28: -43.930637 | AB28: CHACARA DO TENENTE | CJ28: 20260528008400704 29.05.2026 17:41:05 U5513370 APELIDO: NÃO INFORMADO CLASSE DE CONSUMO: RESIDENCIAL Descrição problema NOME DO CLIENTE: RAIMUNDA DO LAGO CASTRO FINANCIAMENTO DE PADRÃO PARCELADO EM: 24_-_R$_18,03 PONTO DE REFERÊNCIA: CHACARA DO TENENTE Rede de MT há 130 metros da residência poste 22151919 para referência SOLICITAÇÃO VIA BACKOFFICE (MA) Nº DO PROTOCOLO DO SITE TELEFONE: (98) 99146-6385 TIPO DE FASE: MONOFÁSICO: medidor_monofasico
B29: 0 | D29: 2306469 | E29: 1113244872 | F29: UNR | G29: 46174 | H29: 0 | I29: CANC | J29: Pré Análise | K29: 0 | L29: MO | M29: PAT2 | N29: CENTRO | O29: TUNTUM | P29: 936.83 | Q29: 251.34 | R29: 261.48 | S29: 23.42075 | T29: 2.7926667 | U29: DIOGO TAVARES DA SILVA | V29: 3026325098 | W29: 2001161410 | X29: PA PACAS S/N / PACAS | Y29: RURAL | Z29: -5.2789508 | AA29: -44.775437 | AB29: ENTRE OS POVOADOS PA PACA E SERRA GRANDE HA 200 METROS DA CASA DO JOSE JEFERSON FILHO DO | CJ29: 200 METROS DA CASA DO JOSE JEFERSON FILHO DO COXINHA POPRIEDADE DO CIDADE TUNTUM DIOGO TAVARES DA SILVA CLIENTE SOLICITOU CONEXAO NOVA COM 01.06.2026 15:58:44 T12490 ? CASO SIM, INFORMAR DADOS DO CARREGADOR : (Potência e modelo da A INSTALAÇÃO POSSUI OU CONTARÁ COM CARREGADORES PARA VEÍCULOS ELÉTRICOS AMPERAGEM DO DISJUNTOR : 25 ANEXO DOC. DO SOLICITANTE, FORMULÁRIO DE CONEXÃO E FORMULÁRIO DE ANÁLISE DUP CADASTRO? SIM ASSINOU FORMULÁRIO DE FINANC. DE PADRÃO? SIM AUTORIZAÇÃO BLITZ URBANA? NÃO CASA EM CONSTRUCAO CLIENTE VEIO AO ATENDIMENTO E SOLICITOU CONEXÃO COM FINANCIAMENTO DE COORD. GEOGRÁFICAS: -5.2783018302665115, -44.775652326919335 DIOGO DA AGROFORT. CC VIZINHA 3019560545 HA 2 KM DA SERRA GRANDE Descrição problema E-MAIL VÁLIDO: ZOOTDIOO@GMAIL.COM ENDEREÇO CORRESPONDÊNCIA: ESTRADA DO PV PACA , PACA - ZONA RURAL, ENDEREÇO DA CONEXÃO É O MESMO ENDEREÇO DE CORRESPONDÊNCIA? SIM FINACIAMENTO DE PADRÃO ASSINADOS.
B30: 0 | D30: 2309309 | E30: 1113410522 | F30: UNI | G30: 46182 | H30: GIRO NO PRAZO | I30: CANC | J30: Pré Análise | K30: 0 | L30: MO | M30: PAT1 | N30: CENTRO | O30: PAULO RAMOS | P30: 60.46 | Q30: 230.54 | R30: 248.91 | S30: 1.5115 | T30: 2.5615556 | U30: FRANCISCO ARAUJO OLIVEIRA | V30: 3026378248 | W30: 2001163426 | X30: COLIBRIS 54 / XEXEU | Y30: URBANO | Z30: -4.4417683 | AA30: -45.245603 | CJ30: 09.06.2026 09:15:02 U5511622 CIENTE DO PRAZO DE 05 DIAS ÚTEIS PARA VISTORIA E EXECUÇÃO DO SERVIÇO. CLIENTE AFIRMA QUE JÁ POSSUI O PADRÃO INSTALADO DENTRO DO LIMITE DA VIA Descrição problema PADRÃO INSTALADO: SIM FASE: monofásico DISJUNTOR: 25a PONTO DE REFERÊNCIA: não informado TELEFONE: (98) 98196-9471 PÚBLICA E CIENTE QUE CASO A INEXISTÊNCIA SEU PEDIDO SERÁ REJEITADO. Rede de BT a mais de 90mts SOLICITAÇÃO VIA BACKOFFICE Nº DO PROTOCOLO DO SITE 20260608000475801
B31: 0 | D31: 2309327 | E31: 1113413457 | F31: UNR | G31: 46182 | H31: 0 | I31: REJE | J31: Concluído | K31: Concluído | L31: 0 | M31: PAT1 | N31: LESTE | O31: PARAIBANO | P31: 87.36 | Q31: 88.85 | R31: 256.27 | S31: 2.184 | T31: 0.98722222 | U31: ROSILENE ALENCAR DA SILVA NOLETO | V31: 3026381575 | W31: 2001163576 | X31: PONTA DA SERRA S/N / MARAJA | Y31: RURAL | Z31: -6.4173617 | AA31: -43.974753 | AB31: PROXIMO A CASA DA ANA PAULA NOLETO E PROXIMO A PLACA ARENA ALEXANDRO | CJ31: 09.06.2026 11:47:06 U5511865 CIENTE DO PRAZO DE 05 DIAS ÚTEIS PARA VISTORIA E EXECUÇÃO DO SERVIÇO. CLIENTE AFIRMA QUE JÁ POSSUI O PADRÃO INSTALADO DENTRO DO LIMITE DA VIA DISJUNTOR:25 A Descrição problema FASE: MONOFASICO NOME: ROSILENE ALENCAR DA SILVA NOLETO Nº DO PROTOCOLO DO SITE 20260608008403043 PADRÃO INSTALADO: SIM PLACA ARENA ALEXANDRO PONTO DE REFERÊNCIA: PROXIMO A CASA DA ANA PAULA NOLETO E PROXIMO A Poste mais próximo 100 metros PÚBLICA E CIENTE QUE CASO A INEXISTÊNCIA SEU PEDIDO SERÁ REJEITADO. SOLICITAÇÃO VIA BACKOFFICE (EQUATORIAL MA) TELEFONE: (99) 98491-2916
B32: 0 | D32: 2310168 | E32: 1113442679 | F32: UNR | G32: 46183 | H32: 0 | I32: REJE | J32: Concluído | K32: Concluído | L32: 0 | M32: PAT1 | N32: LESTE | O32: BURITI | P32: 106.35 | Q32: 29.49 | R32: 122.21 | S32: 2.65875 | T32: 0.32766667 | U32: ANATALIA COSTA DE FRANCA | V32: 3026395070 | W32: 2001163990 | X32: BOM JESUS S/N / LAGOA | Y32: RURAL | Z32: -3.945415 | AA32: -42.967588 | AB32: DEPOIS DA FAZENDA BOM ESPERANCA, VIZINHO DA LENIA | CJ32: 10.06.2026 11:51:37 F39989912 150 metros longe da rede ANATALIA COSTA DE FRANCA VEIO AO ATENDIMENTO E SOLICITOU CONEXÃO. ANEXO DOC. DO SOLICITANTE E FORMULÁRIO DE CONEXÃO ASSINADO.TERMOS ANÁLISE DUP CADASTRO? NÃO CHECKLIST PADRÃO MONTADO ASSINADO PELO CLIENTE? SIM CIENTE DO PRAZO DE VISTORIA E QUE EM CASO DE PADRÃO INCOMPLETO/ COORD. GEOGRÁFICAS: NÃO INFORMADO Cliente não se encontra pra fazer o financiamento casa fechada DEVIDAMENTE ANEXADOS NO CRM E CSS Descrição problema E-MAIL VÁLIDO: NÃO INFORMADO ENDEREÇO CORRESPONDÊNCIA: PV BOM JESUS S/N BURITI ZONA RURAL ENDEREÇO DA CONEXÃO É O MESMO ENDEREÇO DE CORRESPONDÊNCIA? SIM INEXISTENTE SEU PEDIDO SERÁ REJEITADO. LIGAÇÃO NOVA COM PADRÃO INSTALADO PADRÃO INSTALADO EXTERNAMENTE? SIM PONTO DE REFERÊNCIA: DEPOIS DA FAZENDA BOM ESPERANCA VIZINHO DA LENIA POSSUI REDE ELÉTRICA PROX. AO IMÓVEL? SIM TELEFONE: 98984387618
B33: 0 | D33: 2309377 | E33: 1113465542 | F33: UNR | G33: 46183 | H33: 0 | I33: REJE | J33: Pré Análise | K33: 0 | L33: 0 | M33: PAT1 | N33: LESTE | O33: BREJO | P33: 183.68 | Q33: 178.42 | R33: 185.48 | S33: 4.592 | T33: 1.9824444 | U33: FLAVIO JOSE MORAES DE SOUSA | V33: 3026402408 | W33: 2001164283 | X33: ESCALVADO S/N / ZONA RURAL | Y33: RURAL | Z33: -3.7514922 | AA33: -42.716524 | CJ33: 10.06.2026 22:27:13 U5514856 BAIRRO: ZONA RURAL CIDADE: BREJO CIENTE DO PRAZO DE 05 DIAS ÚTEIS PARA VISTORIA E EXECUÇÃO DO SERVIÇO CLIENTE A QUE JÁ POSSUI O PADRÃO INSTALADO DENTRO DO LIMITE DA VIA COMPLEMENTO:xxxxxxxxx Cliente Fora de padrão, Sem padrão, e não ta no local para financiar kit poste Cliente fica mais de 300mt da Rede BT e MT a casa fica no fundo da casa que tem um orelhão na porta Descrição problema FASE: Monofásica DISJUNTOR: 50A NOME DO TITULAR: FLAVIO JOSE MORAES DE SOUSA PADRÃO INSTALADO: não PONTO DE REFERÊNCIA:xxxxxxxxx PROTOCOLO DO SITE 20260609000479566 PÚBLICA E CIENTE QUE CASO A INEXISTÊNCIA SEU PEDIDO SERÁ REJEITADO. RUA: ESCALVADO s/n SOLICITAÇÃO BACKOFFICE Telefone: (99) 99167-8647
B34: 0 | D34: 2328156 | E34: 1113680488 | F34: UNR | G34: 46193 | H34: 0 | I34: REJE | J34: Pré Análise | K34: Análise de levantamento | L34: 0 | M34: PAT2 | N34: LESTE | O34: PARAIBANO | P34: 414.43 | Q34: 464.25 | R34: 467.01 | S34: 10.36075 | T34: 5.1583333 | U34: MARDENS ROCHA DE SOUSA | V34: 3026480255 | W34: 2001167443 | X34: RIACHUELO S/N / CENTRO | Y34: RURAL | Z34: -6.4306733 | AA34: -44.016265 | AB34: PROXIMO A PONTE DA CHAPADINA | CJ34: 20.06.2026 07:54:19 U5512599 APELIDO: XXXXXXXXXXX CLASSE DE CONSUMO: RESIDENCIAL Cliente fica a uns 200 metros da BT mais próximo, componente mais próximo 3554465. Descrição problema FINANCIAMENTO DE PADRÃO NOME DO CLIENTE: MARDENS ROCHA DE SOUSA SOLICITA FINANCIAMENTO DE PADRÃO PARCELADO EM:24_-_R$_18 03 X VEZES PONTO DE REFERÊNCIA: PROXIMO A PONTE DA CHAPADINA SOLICITAÇÃO VIA BACKOFFICE MA Nº DO PROTOCOLO DO SITE 20260618008405686 TELEFONE: (99) 98446-1748 TIPO DE FASE: MONOFÁSICO: 25A
B35: 0 | D35: 2331990 | E35: 1113806648 | F35: UNR | G35: 46199 | H35: 0 | I35: REJE | J35: Pré Análise | K35: 0 | L35: 0 | M35: PAT2 | N35: CENTRO | O35: BOM JARDIM | P35: 833.26 | Q35: 302.55 | R35: 653.24 | S35: 20.8315 | T35: 3.3616667 | U35: CLAUDENICE GUAJAJARA BARROS | V35: 3026532271 | W35: 2001169532 | X35: PRINCIPAL 07 / RURAL | Y35: RURAL | Z35: -3.6144964 | AA35: -45.517798 | AB35: TERRA INDIGENA RIO PINDARÉ | CJ35: (SEGUE EM ANEXO) 26.06.2026 11:21:28 L90862636 ANEXO DOC. DO SOLICITANTE FORMULÁRIO DE CONEXÃO E FORMULÁRIO DE PADRAO CLAUDENICE GUAJAJARA BARROS SOLICITA LIGACAO NOVA FAVOR FINANCIAR CLIENTE CIENTE DO PRAZO DE VISTORIA. Descrição problema E-MAIL VÁLIDO: HELIVANDO.SOUSA@FUNAI.GOV.BR ENDERECO ALDEIA GUARIMA TERRA INDIGENA DO RIO PINDARE SEM NUMERO ZONA ENDEREÇO CORRESPONDÊNCIA: ENDERECO ALDEIA GUARIMA TERRA INDIGENA DO RIO ENDEREÇO DA CONEXÃO É O MESMO ENDEREÇO DE CORRESPONDÊNCIA? SIM Levantob. PG mais próximo 13160959 MONTADO. NAO Necessário obra, sem rede e cliente aceita financiamento e sem padrão , código para a nota PADRAO EM CAMPO PINDARE SEM NUMERO ZONA RURAL MUNICIPIO DE BOM JARIM Pg mais próximo 368517 RURAL MUNICIPIO DE BOM JARIM SITUAÇÃO DO CPF DO CLIENTE REGULAR NA RECEITA FEDERAL? ( X ) SIM ( ) SOLICITACAO COM AUTORIZACAO DA GERENTE LAISE AZEVEDO
B36: 0 | D36: 2343646 | E36: 1114167469 | F36: UNR | G36: 46216 | H36: 0 | I36: ATIV | J36: Pré Análise | K36: 0 | L36: 0 | M36: PAT2 | N36: CENTRO | O36: ARARI | P36: 560.67 | Q36: 569.74 | R36: 574.37 | S36: 14.01675 | T36: 6.3304444 | U36: FRANCIMARIO CARVALHO FERNANDES | V36: 3026666936 | W36: 2001174549 | X36: DA ILHOTA S/N, LOTE 04, Q / LOTEAMENTO NATUREZA | Y36: RURAL | Z36: -3.4382883 | AA36: -44.757318 | CJ36: 13.07.2026 17:07:05 RFCUSER CPF: 60185129390 Descrição problema E-mail para recebimento de conta: Mecessita de obra pra atender esse cliente, mais de 900 metros do poste mais próximo várias casas Medidor: 0 Nome civil: FRANCIMARIO CARVALHO FERNANDES Nome: FRANCIMARIO CARVALHO FERNANDES Novo titular: Padrão de instalação: Parcelas: 000 Poste: 0 Representante: Não em construção
B37: 0 | D37: 1981470 | E37: 1109910091 | F37: MGD | G37: 46160 | H37: GIRO FORA PRAZO | I37: RECE | J37: Pré Análise | K37: 0 | L37: 0 | M37: PAT1 | N37: SUL | O37: BALSAS | P37: 42.44 | Q37: 48.2 | R37: 88.48 | S37: 1.061 | T37: 0.53555556 | U37: EDENILTON PINHEIRO SILVA | V37: 3012153650 | W37: 2000095768 | X37: 02 S/N / RURAL | Y37: RURAL | Z37: -7.4594005 | AA37: -46.04267 | AB37: POVOADO, 99 99171-5657 | CJ37: 20260129000236919 Aberto Anexos BackOffice Equatorial Energia Busca de solicitações CPF do responsável técnico 904.217.281-91 CPF ou CNPJ 021.224.843-06 CPF/CNPJ do formulário 021.224.843-06 Celular com DDD (98) 99107-6922 Celular do responsável técnico (63) 98426-7870 Conta Contrato 3012153650 Dados da solicitação Dados gerais Data de abertura 29/01/2026 13:38 Data de criação 29/01/2026 Detalhes da Solicitação Disjuntor de entrada 40 E-mail do responsável técnico davilucasrodriguesjorge@gmail.com Empresa do responsável técnico SE LIGA SOLUCOES Endereço de e-mail para acompanhamento davilucasrodriguesjorge@gmail.com
B38: 0 | D38: 2342107 | E38: 1111114107 | F38: MGD | G38: 46219 | H38: GIRO FORA PRAZO | I38: FINL | J38: Pré Análise | K38: Em levantamento | L38: 0 | M38: PAT2 | N38: CENTRO | O38: FERNANDO FALCAO | P38: 1422.17 | Q38: 58.05 | R38: 60.49 | S38: 35.55425 | T38: 0.645 | U38: HILO DE ALMEIDA SOUSA | V38: 35106936 | W38: 35106936 | X38: MARAVILHA 1 / PV MARAVILHA | Y38: RURAL | Z38: -6.1259482 | AA38: -44.812644 | AB38: TEM QUE IR ACESSO POR FERNANDO FALCAO APOS 20 KM DEPOIS DA PONTE DO RIO PERCATA FICA DO LADO MUNICIP | CJ38: 20260312000302705 Aberto Anexos BackOffice Equatorial Energia Busca de solicitações CPF do responsável técnico 956.170.943-00 CPF ou CNPJ 151.391.404-97 CPF/CNPJ do formulário 151.391.404-97 Celular com DDD (86) 98893-7435 Celular do responsável técnico (86) 98893-7435 Conta Contrato 35106936 Dados da solicitação Dados gerais Data de abertura 12/03/2026 09:09 Data de criação 12/03/2026 Detalhes da Solicitação Disjuntor de entrada 63 E-mail do responsável técnico projetos@madseng.com.br Empresa do responsável técnico MADS ENGENHARIA LTDA Endereço de e-mail para acompanhamento projetos@madseng.com.br
B39: 0 | D39: 1987136 | E39: 1112789893 | F39: MGD | G39: 46170 | H39: GIRO FORA PRAZO | I39: FINL | J39: Pré Análise | K39: 0 | L39: 0 | M39: PAT1 | N39: LESTE | O39: SANTA QUITERIA DO MARANHAO | P39: 69.87 | Q39: 59.75 | R39: 68.13 | S39: 1.74675 | T39: 0.66388889 | U39: ESTADO DO MARANHAO DEFENSORIA | V39: 3025114964 | W39: 2001117569 | X39: PARDAIS S/N / CENTRO | Y39: URBANO | Z39: -3.4919572 | AA39: -42.56392 | AB39: RESIDENCIAL PALMEIRAS, SETOR B. | CJ39: 20260512000425842 Aberto Anexos BackOffice Equatorial Energia Busca de solicitações CPF do responsável técnico 088.776.454-15 CPF ou CNPJ 00.820.295/0001-42 CPF/CNPJ do formulário 00.820.295/0001-42 Celular com DDD (98) 98348-7323 Celular do responsável técnico (84) 99637-6086 Conta Contrato 400318501605 Dados da solicitação Dados gerais Data de abertura 12/05/2026 10:25 Data de criação 12/05/2026 Detalhes da Solicitação Disjuntor de entrada 63 E-mail do responsável técnico financeiro@worldtelecom.com.br Empresa do responsável técnico WORLD TELECOM LTDA Endereço de e-mail para acompanhamento financeiro@worldtelecom.com.br
B40: 0 | D40: 2342096 | E40: 1112857404 | F40: MGD | G40: 46219 | H40: GIRO FORA PRAZO | I40: FINL | J40: Pré Análise | K40: Em levantamento | L40: 0 | M40: PAT1 | N40: CENTRO | O40: BACABAL | P40: 8.84 | Q40: 10.29 | R40: 11.52 | S40: 0.221 | T40: 0.11433333 | U40: ANA VALERIA DA SILVA NOGUEIRA | V40: 3025879758 | W40: 2000916316 | X40: ROMA 24 / RESIDENCIAL VILLAGIO | Y40: URBANO | Z40: -4.244055 | AA40: -44.803165 | AB40: AO LADO DO ARENA CLUB | CJ40: 20260513000427460 Aberto Anexos BackOffice Equatorial Energia Busca de solicitações CPF do responsável técnico 035.298.283-78 CPF ou CNPJ CPF/CNPJ do formulário Celular com DDD (86) 98135-0536 Celular do responsável técnico (99) 99144-9411 Conta Contrato 0 Dados da solicitação Dados gerais Data de abertura 12/05/2026 22:09 Data de criação 13/05/2026 Detalhes da Solicitação Disjuntor de entrada 63 E-mail do responsável técnico eduardofacundejr@gmail.com Empresa do responsável técnico EVOLUCAO SOLAR E ELETRICA LTDA Endereço de e-mail para acompanhamento eduardofacundejr@gmail.com
...

Sheet DADOS
A1: PI'S | E1: NORTE | J1: NOROESTE | O1: SUL | T1: CENTRO | Y1: LESTE
A2: PI | B2: Tipo | C2: Qtd dias | D2: Data final | E2: Gerente | F2: Executivo | G2: Empresa | H2: Contrato | I2: Técnico | J2: Gerente | K2: Executivo | L2: Empresa | M2: Contrato | N2: Técnico | O2: Gerente | P2: Executivo | Q2: Empresa | R2: Contrato | S2: Técnico | T2: Gerente | U2: Executivo | V2: Empresa | W2: Contrato | X2: Técnico | Y2: Gerente | Z2: Executivo | AA2: Empresa | AB2: Contrato | AC2: Técnico | AD2: Tipo de NS|Parceiro | AE2: Resp. Obra | AH2: TIPO DE OBRA NO SISCO | AI2: TIPO DE OBRA | AJ2: SIGLA | AM2: REGIONAL | AN2: SIGLA-MUNICIPIO | AO2: MUNICIPIO | AP2: SIGLA | AR2: ID DO NUMERO | AS2: SIGLA | AU2: OBRA ESPECIAL? | AW2: REGIONAL NORTE | AX2: RESPONSÁVEL EQTL PROJETO/EXECUÇÃO | AY2: ALEATÓRIOENTRE
A3: ASC | B3: MANUTENÇÃO | C3: 175 | D3: =TODAY()+C3 -> 46441 | E3: ALINEZ MARTINS RABELO COSTA | F3: JEFFERSON CARLOS ARAUJO DOS REIS | G3: DPL - 1º | H3: 4600024693 | I3: JOILSON PINHEIRO CASTRO | J3: DANILO ARRAES DOS SANTOS JACINTO | K3: RICARDO DOS ANJOS LIMA | L3: DPL - 1º | M3: 4600024693 | N3: VERIFICAR NO SGO/SISCO/SISCO | O3: RENAN ACCIOLY PIMENTEL | P3: JOSÉ TARCÍSIO FONTELES NETO | Q3: DPL - 3º | R3: 4600024692 | S3: LUIS FELIPE MUNIZ DOS SANTOS SOUSA | T3: LUCIO DANIEL SOARES DOS SANTOS | U3: ADRIANNO BENEDICTO RABELO AQUINO | V3: CGB - 1° | W3: 4600026661 | X3: DAYLLING ALMEIDA | GESIMIEL SIVA | Y3: SIDNEY CORREA DE ALMEIDA JUNIOR | Z3: JOCIMAR GOMES MAGALHAES JUNIOR | AA3: DPL - 1º | AB3: 4600024691 | AC3: RODRIGO PEREIRA DE ALMEIDA | AD3: SOLICITAÇÃO CLIENTE|CLIENTE | AE3: EXCLUSIVA DA DISTRIBUIDORA
A4: ATV | B4: EXPANSÃO | C4: 175 | D4: =TODAY()+C4 -> 46441 | E4: ALINEZ MARTINS RABELO COSTA | F4: JOSELILSON DE SOUZA LIMA | G4: DPL - 1º | H4: 4600024693 | I4: =IFERROR(INDEX(AX:AX,MATCH(#REF!,DADOS!AW:AW,0)),"Verificar tabela da norte") -> Verificar tabela da norte | J4: DANILO ARRAES DOS SANTOS JACINTO | K4: JANDERSON PAIXÃO DOS SANTOS | L4: DPL - 1º | M4: 4600024693 | N4: VERIFICAR NO SGO/SISCO | O4: RENAN ACCIOLY PIMENTEL | P4: LETICIA CRISTINA DA SILVA BARATA | Q4: DPL - 3º | R4: 4600024692 | S4: VERIFICAR NO SGO/SISCO | T4: LUCIO DANIEL SOARES DOS SANTOS | U4: ALEXANDRE LUIS SILVA SANTOS | V4: CGB - 1° | W4: 4600026661 | X4: VERIFICAR NO SGO/SISCO | Y4: SIDNEY CORREA DE ALMEIDA JUNIOR | Z4: MARCO AURELIO NOLETO MENDES DA SILVA | AA4: DPL - 1º | AB4: 4600024691 | AC4: VERIFICAR NO SGO/SISCO | AH4: AMPLIAÇÃO DE FASE | AI4: AF-AMPLIAÇÃO DE FASE | AJ4: AF | AM4: SUL | AN4: =AP4&"-"&AO4 -> ACL-ACAILANDIA | AO4: ACAILANDIA | AP4: ACL | AR4: AL-Alimentador Tronco | AS4: AL | AU4: OE-Obras Juridicas e/ou Especiais | AW4: AGUA DOCE DO MARANHAO | AX4: =INDEX(AY4:BA4,RANDBETWEEN(1,3)) -> KESSEL LEONEL | AY4: BENILSON SOARES SILVA | AZ4: KESSEL LEONEL | BA4: PERICLES PEREIRA
A5: BCP | B5: EXPANSÃO | C5: 175 | D5: =TODAY()+C5 -> 46441 | E5: ALINEZ MARTINS RABELO COSTA | F5: JOSELILSON DE SOUZA LIMA | G5: DPL - 1º | H5: 4600024693 | I5: =IFERROR(INDEX(AX:AX,MATCH(#REF!,DADOS!AW:AW,0)),"Verificar tabela da norte") -> Verificar tabela da norte | J5: DANILO ARRAES DOS SANTOS JACINTO | K5: JANDERSON PAIXÃO DOS SANTOS | L5: DPL - 1º | M5: 4600024693 | N5: VERIFICAR NO SGO/SISCO | O5: RENAN ACCIOLY PIMENTEL | P5: LETICIA CRISTINA DA SILVA BARATA | Q5: DPL - 3º | R5: 4600024692 | S5: VERIFICAR NO SGO/SISCO | T5: LUCIO DANIEL SOARES DOS SANTOS | U5: ALEXANDRE LUIS SILVA SANTOS | V5: CGB - 1° | W5: 4600026661 | X5: VERIFICAR NO SGO/SISCO | Y5: SIDNEY CORREA DE ALMEIDA JUNIOR | Z5: MARCO AURELIO NOLETO MENDES DA SILVA | AA5: DPL - 1º | AB5: 4600024691 | AC5: ARLAN DE SOUSA AMARANTE | AD5: PLANO DETERMINATIVO|INTERNO | AE5: EXCLUSIVA DA DISTRIBUIDORA | AH5: AMPLIAÇÃO DE POTENCIA | AI5: AP-AMPLIAÇÃO DE POTENCIA | AJ5: AP | AM5: LESTE | AN5: =AP5&"-"&AO5 -> AFC-AFONSO CUNHA | AO5: AFONSO CUNHA | AP5: AFC | AR5: BA-Barramento | AS5: BA | AU5: EX-Exceções | AW5: ARAIOSES | AX5: =INDEX(AY5:BA5,RANDBETWEEN(1,3)) -> KESSEL LEONEL | AY5: BENILSON SOARES SILVA | AZ5: KESSEL LEONEL | BA5: PERICLES PEREIRA
A6: BRE | B6: EXPANSÃO | C6: 175 | D6: =TODAY()+C6 -> 46441 | E6: ALINEZ MARTINS RABELO COSTA | F6: JOSELILSON DE SOUZA LIMA | G6: DPL - 1º | H6: 4600024693 | I6: =IFERROR(INDEX(AX:AX,MATCH(#REF!,DADOS!AW:AW,0)),"Verificar tabela da norte") -> Verificar tabela da norte | J6: DANILO ARRAES DOS SANTOS JACINTO | K6: JANDERSON PAIXÃO DOS SANTOS | L6: DPL - 1º | M6: 4600024693 | N6: VERIFICAR NO SGO/SISCO | O6: RENAN ACCIOLY PIMENTEL | P6: LETICIA CRISTINA DA SILVA BARATA | Q6: DPL - 3º | R6: 4600024692 | S6: VERIFICAR NO SGO/SISCO | T6: LUCIO DANIEL SOARES DOS SANTOS | U6: ALEXANDRE LUIS SILVA SANTOS | V6: CGB - 1° | W6: 4600026661 | X6: VERIFICAR NO SGO/SISCO | Y6: SIDNEY CORREA DE ALMEIDA JUNIOR | Z6: MARCO AURELIO NOLETO MENDES DA SILVA | AA6: DPL - 1º | AB6: 4600024691 | AC6: VERIFICAR NO SGO/SISCO | AD6: PLANO DETERMINATIVO|INTERNO | AE6: EXCLUSIVA DA DISTRIBUIDORA | AH6: CONSTRUÇÃO DE AL | AI6: CA-CONSTRUÇÃO DE AL | AJ6: CA | AM6: NORTE | AN6: =AP6&"-"&AO6 -> ADM-AGUA DOCE DO MARANHAO | AO6: AGUA DOCE DO MARANHAO | AP6: ADM | AR6: CC-Conta Contrato | AS6: CC | AW6: MAGALHAES DE ALMEIDA | AX6: =INDEX(AY6:BA6,RANDBETWEEN(1,3)) -> PERICLES PEREIRA | AY6: BENILSON SOARES SILVA | AZ6: KESSEL LEONEL | BA6: PERICLES PEREIRA
A7: BRT | B7: EXPANSÃO | C7: 175 | D7: =TODAY()+C7 -> 46441 | E7: ALINEZ MARTINS RABELO COSTA | F7: JOSELILSON DE SOUZA LIMA | G7: DPL - 1º | H7: 4600024693 | I7: =IFERROR(INDEX(AX:AX,MATCH(#REF!,DADOS!AW:AW,0)),"Verificar tabela da norte") -> Verificar tabela da norte | J7: DANILO ARRAES DOS SANTOS JACINTO | K7: JANDERSON PAIXÃO DOS SANTOS | L7: DPL - 1º | M7: 4600024693 | N7: JOSE GEORGE VIEGAS SILVA | O7: RENAN ACCIOLY PIMENTEL | P7: LETICIA CRISTINA DA SILVA BARATA | Q7: DPL - 3º | R7: 4600024692 | S7: LUCAS SILVA OLIVEIRA | T7: LUCIO DANIEL SOARES DOS SANTOS | U7: ALEXANDRE LUIS SILVA SANTOS | V7: CGB - 1° | W7: 4600026661 | X7: OTTON CILIO CORREA DA SILVA | Y7: SIDNEY CORREA DE ALMEIDA JUNIOR | Z7: MARCO AURELIO NOLETO MENDES DA SILVA | AA7: DPL - 1º | AB7: 4600024691 | AC7: ARLAN DE SOUSA AMARANTE | AD7: PLANO DETERMINATIVO|INTERNO | AE7: EXCLUSIVA DA DISTRIBUIDORA | AH7: CONSTRUÇÃO DE RD | AI7: CT-CONSTRUÇÃO DE RD | AJ7: CT | AM7: NOROESTE | AN7: =AP7&"-"&AO7 -> ACT-ALCANTARA | AO7: ALCANTARA | AP7: ACT | AR7: ID-IDENTIFICADOR | AS7: ID | AW7: PAULINO NEVES | AX7: =INDEX(AY7:BA7,RANDBETWEEN(1,3)) -> PERICLES PEREIRA | AY7: BENILSON SOARES SILVA | AZ7: KESSEL LEONEL | BA7: PERICLES PEREIRA
A8: CCF | B8: EXPANSÃO | C8: 175 | D8: =TODAY()+C8 -> 46441 | E8: ALINEZ MARTINS RABELO COSTA | F8: JOSELILSON DE SOUZA LIMA | G8: DPL - 1º | H8: 4600024693 | I8: =IFERROR(INDEX(AX:AX,MATCH(#REF!,DADOS!AW:AW,0)),"Verificar tabela da norte") -> Verificar tabela da norte | J8: DANILO ARRAES DOS SANTOS JACINTO | K8: JANDERSON PAIXÃO DOS SANTOS | L8: DPL - 1º | M8: 4600024693 | N8: BENERALDO RABELO FILHO | O8: RENAN ACCIOLY PIMENTEL | P8: LETICIA CRISTINA DA SILVA BARATA | Q8: DPL - 3º | R8: 4600024692 | S8: LUCAS SILVA OLIVEIRA | T8: LUCIO DANIEL SOARES DOS SANTOS | U8: ALEXANDRE LUIS SILVA SANTOS | V8: CGB - 1° | W8: 4600026661 | X8: FABRICIO ANTONIO OLIVIEIRA MOTA | Y8: SIDNEY CORREA DE ALMEIDA JUNIOR | Z8: MARCO AURELIO NOLETO MENDES DA SILVA | AA8: DPL - 1º | AB8: 4600024691 | AC8: MARK SUEL FURTADO | AD8: SOLICITAÇÃO CLIENTE|CLIENTE | AE8: EXCLUSIVA DA DISTRIBUIDORA | AH8: DIVISÃO DE CIRCUITO | AI8: DV-DIVISÃO DE CIRCUITO | AJ8: DV | AM8: LESTE | AN8: =AP8&"-"&AO8 -> ADA-ALDEIAS ALTAS | AO8: ALDEIAS ALTAS | AP8: ADA | AR8: PF-CPF do cliente | AS8: PF | AW8: SANTANA DO MARANHAO | AX8: =INDEX(AY8:BA8,RANDBETWEEN(1,3)) -> PERICLES PEREIRA | AY8: BENILSON SOARES SILVA | AZ8: KESSEL LEONEL | BA8: PERICLES PEREIRA
A9: DIF | B9: EXPANSÃO | C9: 175 | D9: =TODAY()+C9 -> 46441 | E9: ALINEZ MARTINS RABELO COSTA | F9: JOSELILSON DE SOUZA LIMA | G9: DPL - 1º | H9: 4600024693 | I9: =IFERROR(INDEX(AX:AX,MATCH(#REF!,DADOS!AW:AW,0)),"Verificar tabela da norte") -> Verificar tabela da norte | J9: DANILO ARRAES DOS SANTOS JACINTO | K9: JANDERSON PAIXÃO DOS SANTOS | L9: DPL - 1º | M9: 4600024693 | N9: BENERALDO RABELO FILHO | O9: RENAN ACCIOLY PIMENTEL | P9: LETICIA CRISTINA DA SILVA BARATA | Q9: DPL - 3º | R9: 4600024692 | S9: LUCAS SILVA OLIVEIRA | T9: LUCIO DANIEL SOARES DOS SANTOS | U9: ALEXANDRE LUIS SILVA SANTOS | V9: CGB - 1° | W9: 4600026661 | X9: FABRICIO ANTONIO OLIVIEIRA MOTA | Y9: SIDNEY CORREA DE ALMEIDA JUNIOR | Z9: MARCO AURELIO NOLETO MENDES DA SILVA | AA9: DPL - 1º | AB9: 4600024691 | AC9: MARK SUEL FURTADO | AD9: SOLICITAÇÃO CLIENTE|CLIENTE | AE9: EXCLUSIVA DA DISTRIBUIDORA | AH9: FLEXIBILIZAÇÃO DE CIRCUITO | AI9: FC-FLEXIBILIZAÇÃO DE CIRCUITO | AJ9: FC | AM9: CENTRO | AN9: =AP9&"-"&AO9 -> ALM-ALTAMIRA DO MARANHAO | AO9: ALTAMIRA DO MARANHAO | AP9: ALM | AR9: NS-Nota CCS | AS9: NS | AW9: SAO BERNARDO | AX9: =INDEX(AY9:BA9,RANDBETWEEN(1,3)) -> PERICLES PEREIRA | AY9: BENILSON SOARES SILVA | AZ9: KESSEL LEONEL | BA9: PERICLES PEREIRA
A10: DIS | B10: EXPANSÃO | C10: 220 | D10: =TODAY()+C10 -> 46486 | E10: ALINEZ MARTINS RABELO COSTA | F10: JOSELILSON DE SOUZA LIMA | G10: DPL - 1º | H10: 4600024693 | I10: =IFERROR(INDEX(AX:AX,MATCH(#REF!,DADOS!AW:AW,0)),"Verificar tabela da norte") -> Verificar tabela da norte | J10: DANILO ARRAES DOS SANTOS JACINTO | K10: JANDERSON PAIXÃO DOS SANTOS | L10: DPL - 1º | M10: 4600024693 | N10: SANDRO HENRIQUE GOMES | O10: RENAN ACCIOLY PIMENTEL | P10: LETICIA CRISTINA DA SILVA BARATA | Q10: DPL - 3º | R10: 4600024692 | S10: VERIFICAR NO SGO/SISCO | T10: LUCIO DANIEL SOARES DOS SANTOS | U10: ALEXANDRE LUIS SILVA SANTOS | V10: CGB - 1° | W10: 4600026661 | X10: NEYVALDO LOPES MORAES | Y10: SIDNEY CORREA DE ALMEIDA JUNIOR | Z10: MARCO AURELIO NOLETO MENDES DA SILVA | AA10: DPL - 1º | AB10: 4600024691 | AC10: ARLAN DE SOUSA AMARANTE | AD10: PLANO DETERMINATIVO|INTERNO | AE10: EXCLUSIVA DA DISTRIBUIDORA | AH10: INSTALAÇÃO DE EQUIPAMENTOS | AI10: IE-INSTALAÇÃO DE EQUIPAMENTOS | AJ10: IE | AM10: CENTRO | AN10: =AP10&"-"&AO10 -> AAM-ALTO ALEGRE DO MARANHAO | AO10: ALTO ALEGRE DO MARANHAO | AP10: AAM | AR10: NR-Nota de Reclamação | AS10: NR | AW10: TUTOIA | AX10: =INDEX(AY10:BA10,RANDBETWEEN(1,3)) -> KESSEL LEONEL | AY10: BENILSON SOARES SILVA | AZ10: KESSEL LEONEL | BA10: PERICLES PEREIRA
A11: EME | B11: MANUTENÇÃO | C11: 160 | D11: =TODAY()+C11 -> 46426 | E11: ALINEZ MARTINS RABELO COSTA | F11: JEFFERSON CARLOS ARAUJO DOS REIS | G11: DPL - 1º | H11: 4600024693 | I11: JOILSON PINHEIRO CASTRO | J11: DANILO ARRAES DOS SANTOS JACINTO | K11: RICARDO DOS ANJOS LIMA | L11: DPL - 1º | M11: 4600024693 | N11: VERIFICAR NO SGO/SISCO | O11: RENAN ACCIOLY PIMENTEL | P11: JOSÉ TARCÍSIO FONTELES NETO | Q11: DPL - 3º | R11: 4600024692 | S11: VERIFICAR NO SGO/SISCO | T11: LUCIO DANIEL SOARES DOS SANTOS | U11: ADRIANNO BENEDICTO RABELO AQUINO | V11: CGB - 1° | W11: 4600026661 | X11: VERIFICAR NO SGO/SISCO | Y11: SIDNEY CORREA DE ALMEIDA JUNIOR | Z11: JOCIMAR GOMES MAGALHAES JUNIOR | AA11: DPL - 1º | AB11: 4600024691 | AC11: VERIFICAR NO SGO/SISCO | AH11: INSTALAÇÃO DE TRANSFORMADORES | AI11: IT-INSTALAÇÃO DE TRANSFORMADORES | AJ11: IT | AM11: CENTRO | AN11: =AP11&"-"&AO11 -> AAP-ALTO ALEGRE DO PINDARE | AO11: ALTO ALEGRE DO PINDARE | AP11: AAP | AR11: CO-Numero Componente | AS11: CO | AW11: BARREIRINHAS | AX11: =INDEX(AY11:BA11,RANDBETWEEN(1,2)) -> SEBASTIÃO JORGE | AY11: SEBASTIÃO JORGE | AZ11: RAISSA NAIARARA OLIVEIRA | BA11: ISMAR SOUSA
A12: ERD | B12: MANUTENÇÃO | C12: 175 | D12: =TODAY()+C12 -> 46441 | E12: ALINEZ MARTINS RABELO COSTA | F12: JEFFERSON CARLOS ARAUJO DOS REIS | G12: DPL - 1º | H12: 4600024693 | I12: JOILSON PINHEIRO CASTRO | J12: DANILO ARRAES DOS SANTOS JACINTO | K12: RICARDO DOS ANJOS LIMA | L12: DPL - 1º | M12: 4600024693 | N12: ADRIANDO MENDES COSTA | O12: RENAN ACCIOLY PIMENTEL | P12: JOSÉ TARCÍSIO FONTELES NETO | Q12: DPL - 3º | R12: 4600024692 | S12: LUCAS DAVI DOS SANTOS SILVA | T12: LUCIO DANIEL SOARES DOS SANTOS | U12: ADRIANNO BENEDICTO RABELO AQUINO | V12: CGB - 1° | W12: 4600026661 | X12: OTTON CILIO CORREA DA SILVA | Y12: SIDNEY CORREA DE ALMEIDA JUNIOR | Z12: JOCIMAR GOMES MAGALHAES JUNIOR | AA12: DPL - 1º | AB12: 4600024691 | AC12: ARLAN DE SOUSA AMARANTE | AD12: PLANO DETERMINATIVO|INTERNO | AE12: EXCLUSIVA DA DISTRIBUIDORA | AH12: MELHORIA DE REDE | AI12: ME-MELHORIA DE REDE DE DISTRIBUIÇÃO | AJ12: ME | AM12: SUL | AN12: =AP12&"-"&AO12 -> ALP-ALTO PARNAIBA | AO12: ALTO PARNAIBA | AP12: ALP | AR12: OC-Ocorrência | AS12: OC | AW12: HUMBERTO DE CAMPOS | AX12: =INDEX(AY12:BA12,RANDBETWEEN(1,2)) -> RAISSA NAIARARA OLIVEIRA | AY12: SEBASTIÃO JORGE | AZ12: RAISSA NAIARARA OLIVEIRA | BA12: ISMAR SOUSA
A13: EUR | B13: EXPANSÃO | C13: 175 | D13: =TODAY()+C13 -> 46441 | E13: ALINEZ MARTINS RABELO COSTA | F13: JOSELILSON DE SOUZA LIMA | G13: DPL - 1º | H13: 4600024693 | I13: =IFERROR(INDEX(AX:AX,MATCH(#REF!,DADOS!AW:AW,0)),"Verificar tabela da norte") -> Verificar tabela da norte | J13: DANILO ARRAES DOS SANTOS JACINTO | K13: JANDERSON PAIXÃO DOS SANTOS | L13: DPL - 1º | M13: 4600024693 | N13: VERIFICAR NO SGO/SISCO | O13: RENAN ACCIOLY PIMENTEL | P13: LETICIA CRISTINA DA SILVA BARATA | Q13: DPL - 3º | R13: 4600024692 | S13: GILVAN CARDOSO VIANA | T13: LUCIO DANIEL SOARES DOS SANTOS | U13: ALEXANDRE LUIS SILVA SANTOS | V13: CGB - 1° | W13: 4600026661 | X13: VERIFICAR NO SGO/SISCO | Y13: SIDNEY CORREA DE ALMEIDA JUNIOR | Z13: MARCO AURELIO NOLETO MENDES DA SILVA | AA13: DPL - 1º | AB13: 4600024691 | AC13: JONAS FELIPE AS MELO | AD13: SOLICITAÇÃO CLIENTE|CLIENTE | AE13: EXCLUSIVA DA DISTRIBUIDORA | AH13: MICROSSISTEMA ISOLADO DE | AI13: MI-MICROSSISTEMA ISOLADO DE GERAÇÃO DE ENERGIA | AJ13: MI | AM13: NOROESTE | AN13: =AP13&"-"&AO13 -> AMM-AMAPA DO MARANHAO | AO13: AMAPA DO MARANHAO | AP13: AMM | AR13: PT-Parecer Técnico | AS13: PT | AW13: PRIMEIRA CRUZ | AX13: =INDEX(AY13:BA13,RANDBETWEEN(1,2)) -> RAISSA NAIARARA OLIVEIRA | AY13: SEBASTIÃO JORGE | AZ13: RAISSA NAIARARA OLIVEIRA | BA13: ISMAR SOUSA
A14: FIM | B14: MANUTENÇÃO | C14: 190 | D14: =TODAY()+C14 -> 46456 | E14: ALINEZ MARTINS RABELO COSTA | F14: JEFFERSON CARLOS ARAUJO DOS REIS | G14: DPL - 1º | H14: 4600024693 | I14: JOILSON PINHEIRO CASTRO | J14: DANILO ARRAES DOS SANTOS JACINTO | K14: RICARDO DOS ANJOS LIMA | L14: DPL - 1º | M14: 4600024693 | N14: JOSE MARCIANO SILVA | O14: RENAN ACCIOLY PIMENTEL | P14: JOSÉ TARCÍSIO FONTELES NETO | Q14: DPL - 3º | R14: 4600024692 | S14: LUIS FELIPE MUNIZ DOS SANTOS | T14: LUCIO DANIEL SOARES DOS SANTOS | U14: ADRIANNO BENEDICTO RABELO AQUINO | V14: CGB - 1° | W14: 4600026661 | X14: NEYVALDO LOPES | ANDERSON APOLIANO | Y14: SIDNEY CORREA DE ALMEIDA JUNIOR | Z14: JOCIMAR GOMES MAGALHAES JUNIOR | AA14: DPL - 1º | AB14: 4600024691 | AC14: ARLAN DE SOUSA AMARANTE | AD14: PLANO DETERMINATIVO|INTERNO | AE14: EXCLUSIVA DA DISTRIBUIDORA | AH14: REALOCAÇÃO DE POSTE | AI14: MP-REALOCAÇÃO DE POSTE | AJ14: MP | AM14: SUL | AN14: =AP14&"-"&AO14 -> AMO-AMARANTE DO MARANHAO | AO14: AMARANTE DO MARANHAO | AP14: AMO | AR14: PG-Ponto Geográfico | AS14: PG | AW14: SANTO AMARO DO MARANHAO | AX14: =INDEX(AY14:BA14,RANDBETWEEN(1,2)) -> SEBASTIÃO JORGE | AY14: SEBASTIÃO JORGE | AZ14: RAISSA NAIARARA OLIVEIRA | BA14: ISMAR SOUSA
